2024-05-07 19:32:22,818 FILE: creds.py IN: create_new_token MESSAGE: Ошибка получения iam_token: HTTPConnectionPool(host='169.254.169.254', port=80): Max retries exceeded with url: /computeMetadata/v1/instance/service-accounts/default/token (Caused by ConnectTimeoutError(<urllib3.connection.HTTPConnection object at 0x000001B4BAE4D910>, 'Connection to 169.254.169.254 timed out. (connect timeout=None)'))
2024-05-07 19:32:43,873 FILE: creds.py IN: create_new_token MESSAGE: Ошибка получения iam_token: HTTPConnectionPool(host='169.254.169.254', port=80): Max retries exceeded with url: /computeMetadata/v1/instance/service-accounts/default/token (Caused by ConnectTimeoutError(<urllib3.connection.HTTPConnection object at 0x000001B4BB09F5D0>, 'Connection to 169.254.169.254 timed out. (connect timeout=None)'))
2024-05-07 19:33:48,435 FILE: database.py IN: add_message MESSAGE: Error binding parameter 5: type 'tuple' is not supported
2024-05-07 19:34:22,253 FILE: database.py IN: add_message MESSAGE: Error binding parameter 6: type 'tuple' is not supported
